[2025-08-21T19:04:09.987+0000] {taskinstance.py:1157} INFO - Dependencies all met for dep_context=non-requeueable deps ti=<TaskInstance: crypto_ml_pipeline.retrain_model manual__2025-08-21T19:03:59.030427+00:00 [queued]>
[2025-08-21T19:04:09.990+0000] {taskinstance.py:1157} INFO - Dependencies all met for dep_context=requeueable deps ti=<TaskInstance: crypto_ml_pipeline.retrain_model manual__2025-08-21T19:03:59.030427+00:00 [queued]>
[2025-08-21T19:04:09.990+0000] {taskinstance.py:1359} INFO - Starting attempt 1 of 2
[2025-08-21T19:04:09.995+0000] {taskinstance.py:1380} INFO - Executing <Task(PythonOperator): retrain_model> on 2025-08-21 19:03:59.030427+00:00
[2025-08-21T19:04:09.998+0000] {standard_task_runner.py:57} INFO - Started process 704 to run task
[2025-08-21T19:04:09.999+0000] {standard_task_runner.py:84} INFO - Running: ['airflow', 'tasks', 'run', 'crypto_ml_pipeline', 'retrain_model', 'manual__2025-08-21T19:03:59.030427+00:00', '--job-id', '56', '--raw', '--subdir', 'DAGS_FOLDER/crypto_ml_pipeline.py', '--cfg-path', '/tmp/tmpz66lryqz']
[2025-08-21T19:04:10.000+0000] {standard_task_runner.py:85} INFO - Job 56: Subtask retrain_model
[2025-08-21T19:04:10.018+0000] {task_command.py:415} INFO - Running <TaskInstance: crypto_ml_pipeline.retrain_model manual__2025-08-21T19:03:59.030427+00:00 [running]> on host c7ecf678507a
[2025-08-21T19:04:10.043+0000] {taskinstance.py:1660} INFO - Exporting env vars: AIRFLOW_CTX_DAG_OWNER='crypto-mlops' AIRFLOW_CTX_DAG_ID='crypto_ml_pipeline' AIRFLOW_CTX_TASK_ID='retrain_model' AIRFLOW_CTX_EXECUTION_DATE='2025-08-21T19:03:59.030427+00:00' AIRFLOW_CTX_TRY_NUMBER='1' AIRFLOW_CTX_DAG_RUN_ID='manual__2025-08-21T19:03:59.030427+00:00'
[2025-08-21T19:04:10.044+0000] {logging_mixin.py:151} INFO - ü§ñ Retraining ML model...
[2025-08-21T19:04:10.081+0000] {logging_mixin.py:151} INFO - üìä Training data shape: (929, 16)
[2025-08-21T19:04:10.108+0000] {logging_mixin.py:151} WARNING - 2025/08/21 19:04:10 WARNING mlflow.utils.git_utils: Failed to import Git (the Git executable is probably not on your PATH), so Git SHA is not available. Error: Failed to initialize: Bad git executable.
The git executable must be specified in one of the following ways:
    - be included in your $PATH
    - be set via $GIT_PYTHON_GIT_EXECUTABLE
    - explicitly set via git.refresh(<full-path-to-git-executable>)

All git commands will error until this is rectified.

This initial message can be silenced or aggravated in the future by setting the
$GIT_PYTHON_REFRESH environment variable. Use one of the following values:
    - quiet|q|silence|s|silent|none|n|0: for no message or exception
    - warn|w|warning|log|l|1: for a warning message (logging level CRITICAL, displayed by default)
    - error|e|exception|raise|r|2: for a raised exception

Example:
    export GIT_PYTHON_REFRESH=quiet
[2025-08-21T19:04:10.129+0000] {logging_mixin.py:151} INFO - ‚è≥ Training model...
[2025-08-21T19:04:20.162+0000] {credentials.py:1123} INFO - Found credentials in environment variables.
[2025-08-21T19:04:20.359+0000] {logging_mixin.py:151} INFO - ‚úÖ Model training completed. Run ID: 0875f062028145dab523166f74bd61ab
[2025-08-21T19:04:20.369+0000] {logging_mixin.py:151} WARNING - 2025/08/21 19:04:20 INFO mlflow.tracking._tracking_service.client: üèÉ View run clumsy-snake-554 at: http://mlflow:5000/#/experiments/1/runs/0875f062028145dab523166f74bd61ab.
[2025-08-21T19:04:20.369+0000] {logging_mixin.py:151} WARNING - 2025/08/21 19:04:20 INFO mlflow.tracking._tracking_service.client: üß™ View experiment at: http://mlflow:5000/#/experiments/1.
[2025-08-21T19:04:20.375+0000] {python.py:194} INFO - Done. Returned value was: {'run_id': '0875f062028145dab523166f74bd61ab', 'mse': 0.004038909345726717, 'mae': 0.013702104606510527, 'training_date': '2025-08-21'}
[2025-08-21T19:04:20.385+0000] {taskinstance.py:1398} INFO - Marking task as SUCCESS. dag_id=crypto_ml_pipeline, task_id=retrain_model, execution_date=20250821T190359, start_date=20250821T190409, end_date=20250821T190420
[2025-08-21T19:04:20.411+0000] {local_task_job_runner.py:228} INFO - Task exited with return code 0
[2025-08-21T19:04:20.418+0000] {taskinstance.py:2776} INFO - 1 downstream tasks scheduled from follow-on schedule check
