[2025-08-21T18:13:12.604+0000] {taskinstance.py:1157} INFO - Dependencies all met for dep_context=non-requeueable deps ti=<TaskInstance: crypto_ml_pipeline.retrain_model manual__2025-08-21T18:13:03.184220+00:00 [queued]>
[2025-08-21T18:13:12.606+0000] {taskinstance.py:1157} INFO - Dependencies all met for dep_context=requeueable deps ti=<TaskInstance: crypto_ml_pipeline.retrain_model manual__2025-08-21T18:13:03.184220+00:00 [queued]>
[2025-08-21T18:13:12.606+0000] {taskinstance.py:1359} INFO - Starting attempt 1 of 2
[2025-08-21T18:13:12.611+0000] {taskinstance.py:1380} INFO - Executing <Task(PythonOperator): retrain_model> on 2025-08-21 18:13:03.184220+00:00
[2025-08-21T18:13:12.614+0000] {standard_task_runner.py:57} INFO - Started process 473 to run task
[2025-08-21T18:13:12.616+0000] {standard_task_runner.py:84} INFO - Running: ['airflow', 'tasks', 'run', 'crypto_ml_pipeline', 'retrain_model', 'manual__2025-08-21T18:13:03.184220+00:00', '--job-id', '40', '--raw', '--subdir', 'DAGS_FOLDER/crypto_ml_pipeline.py', '--cfg-path', '/tmp/tmpn4_upvtv']
[2025-08-21T18:13:12.617+0000] {standard_task_runner.py:85} INFO - Job 40: Subtask retrain_model
[2025-08-21T18:13:12.633+0000] {task_command.py:415} INFO - Running <TaskInstance: crypto_ml_pipeline.retrain_model manual__2025-08-21T18:13:03.184220+00:00 [running]> on host 73c7f9ebdbc7
[2025-08-21T18:13:12.657+0000] {taskinstance.py:1660} INFO - Exporting env vars: AIRFLOW_CTX_DAG_OWNER='crypto-mlops' AIRFLOW_CTX_DAG_ID='crypto_ml_pipeline' AIRFLOW_CTX_TASK_ID='retrain_model' AIRFLOW_CTX_EXECUTION_DATE='2025-08-21T18:13:03.184220+00:00' AIRFLOW_CTX_TRY_NUMBER='1' AIRFLOW_CTX_DAG_RUN_ID='manual__2025-08-21T18:13:03.184220+00:00'
[2025-08-21T18:13:12.658+0000] {logging_mixin.py:151} INFO - ü§ñ Retraining ML model...
[2025-08-21T18:13:12.694+0000] {logging_mixin.py:151} INFO - üìä Training data shape: (929, 16)
[2025-08-21T18:13:12.715+0000] {logging_mixin.py:151} WARNING - 2025/08/21 18:13:12 WARNING mlflow.utils.git_utils: Failed to import Git (the Git executable is probably not on your PATH), so Git SHA is not available. Error: Failed to initialize: Bad git executable.
The git executable must be specified in one of the following ways:
    - be included in your $PATH
    - be set via $GIT_PYTHON_GIT_EXECUTABLE
    - explicitly set via git.refresh(<full-path-to-git-executable>)

All git commands will error until this is rectified.

This initial message can be silenced or aggravated in the future by setting the
$GIT_PYTHON_REFRESH environment variable. Use one of the following values:
    - quiet|q|silence|s|silent|none|n|0: for no message or exception
    - warn|w|warning|log|l|1: for a warning message (logging level CRITICAL, displayed by default)
    - error|e|exception|raise|r|2: for a raised exception

Example:
    export GIT_PYTHON_REFRESH=quiet
[2025-08-21T18:13:12.735+0000] {logging_mixin.py:151} INFO - ‚è≥ Training model...
[2025-08-21T18:13:22.786+0000] {credentials.py:1123} INFO - Found credentials in environment variables.
[2025-08-21T18:13:22.976+0000] {logging_mixin.py:151} INFO - ‚úÖ Model training completed. Run ID: bbb6ab76088446b7a1c9fb89a3b4ad91
[2025-08-21T18:13:22.982+0000] {logging_mixin.py:151} WARNING - 2025/08/21 18:13:22 INFO mlflow.tracking._tracking_service.client: üèÉ View run rebellious-owl-563 at: http://mlflow:5000/#/experiments/1/runs/bbb6ab76088446b7a1c9fb89a3b4ad91.
[2025-08-21T18:13:22.982+0000] {logging_mixin.py:151} WARNING - 2025/08/21 18:13:22 INFO mlflow.tracking._tracking_service.client: üß™ View experiment at: http://mlflow:5000/#/experiments/1.
[2025-08-21T18:13:22.989+0000] {python.py:194} INFO - Done. Returned value was: {'run_id': 'bbb6ab76088446b7a1c9fb89a3b4ad91', 'mse': 0.0010030314093760536, 'mae': 0.02290907104004222, 'training_date': '2025-08-21'}
[2025-08-21T18:13:22.998+0000] {taskinstance.py:1398} INFO - Marking task as SUCCESS. dag_id=crypto_ml_pipeline, task_id=retrain_model, execution_date=20250821T181303, start_date=20250821T181312, end_date=20250821T181322
[2025-08-21T18:13:23.020+0000] {local_task_job_runner.py:228} INFO - Task exited with return code 0
[2025-08-21T18:13:23.027+0000] {taskinstance.py:2776} INFO - 1 downstream tasks scheduled from follow-on schedule check
