[2025-08-21T17:36:18.914+0000] {taskinstance.py:1157} INFO - Dependencies all met for dep_context=non-requeueable deps ti=<TaskInstance: crypto_ml_pipeline.retrain_model manual__2025-08-21T17:36:10.515241+00:00 [queued]>
[2025-08-21T17:36:18.918+0000] {taskinstance.py:1157} INFO - Dependencies all met for dep_context=requeueable deps ti=<TaskInstance: crypto_ml_pipeline.retrain_model manual__2025-08-21T17:36:10.515241+00:00 [queued]>
[2025-08-21T17:36:18.918+0000] {taskinstance.py:1359} INFO - Starting attempt 1 of 2
[2025-08-21T17:36:18.922+0000] {taskinstance.py:1380} INFO - Executing <Task(PythonOperator): retrain_model> on 2025-08-21 17:36:10.515241+00:00
[2025-08-21T17:36:18.925+0000] {standard_task_runner.py:57} INFO - Started process 2144 to run task
[2025-08-21T17:36:18.927+0000] {standard_task_runner.py:84} INFO - Running: ['airflow', 'tasks', 'run', 'crypto_ml_pipeline', 'retrain_model', 'manual__2025-08-21T17:36:10.515241+00:00', '--job-id', '33', '--raw', '--subdir', 'DAGS_FOLDER/crypto_ml_pipeline.py', '--cfg-path', '/tmp/tmpphs6oqom']
[2025-08-21T17:36:18.928+0000] {standard_task_runner.py:85} INFO - Job 33: Subtask retrain_model
[2025-08-21T17:36:18.945+0000] {task_command.py:415} INFO - Running <TaskInstance: crypto_ml_pipeline.retrain_model manual__2025-08-21T17:36:10.515241+00:00 [running]> on host 4a23fab12d5a
[2025-08-21T17:36:18.972+0000] {taskinstance.py:1660} INFO - Exporting env vars: AIRFLOW_CTX_DAG_OWNER='crypto-mlops' AIRFLOW_CTX_DAG_ID='crypto_ml_pipeline' AIRFLOW_CTX_TASK_ID='retrain_model' AIRFLOW_CTX_EXECUTION_DATE='2025-08-21T17:36:10.515241+00:00' AIRFLOW_CTX_TRY_NUMBER='1' AIRFLOW_CTX_DAG_RUN_ID='manual__2025-08-21T17:36:10.515241+00:00'
[2025-08-21T17:36:18.973+0000] {logging_mixin.py:151} INFO - ü§ñ Retraining ML model...
[2025-08-21T17:36:19.008+0000] {logging_mixin.py:151} INFO - üìä Training data shape: (929, 16)
[2025-08-21T17:36:19.027+0000] {logging_mixin.py:151} WARNING - 2025/08/21 17:36:19 WARNING mlflow.utils.git_utils: Failed to import Git (the Git executable is probably not on your PATH), so Git SHA is not available. Error: Failed to initialize: Bad git executable.
The git executable must be specified in one of the following ways:
    - be included in your $PATH
    - be set via $GIT_PYTHON_GIT_EXECUTABLE
    - explicitly set via git.refresh(<full-path-to-git-executable>)

All git commands will error until this is rectified.

This initial message can be silenced or aggravated in the future by setting the
$GIT_PYTHON_REFRESH environment variable. Use one of the following values:
    - quiet|q|silence|s|silent|none|n|0: for no message or exception
    - warn|w|warning|log|l|1: for a warning message (logging level CRITICAL, displayed by default)
    - error|e|exception|raise|r|2: for a raised exception

Example:
    export GIT_PYTHON_REFRESH=quiet
[2025-08-21T17:36:19.046+0000] {logging_mixin.py:151} INFO - ‚è≥ Training model...
[2025-08-21T17:36:30.282+0000] {logging_mixin.py:151} WARNING - 2025/08/21 17:36:30 INFO mlflow.tracking._tracking_service.client: üèÉ View run colorful-shrew-573 at: http://mlflow:5000/#/experiments/1/runs/b8539b2a4d404c3abd836ddfc85db76e.
[2025-08-21T17:36:30.282+0000] {logging_mixin.py:151} WARNING - 2025/08/21 17:36:30 INFO mlflow.tracking._tracking_service.client: üß™ View experiment at: http://mlflow:5000/#/experiments/1.
[2025-08-21T17:36:30.288+0000] {taskinstance.py:1935} ERROR - Task failed with exception
Traceback (most recent call last):
  File "/home/airflow/.local/lib/python3.8/site-packages/airflow/operators/python.py", line 192, in execute
    return_value = self.execute_callable()
  File "/home/airflow/.local/lib/python3.8/site-packages/airflow/operators/python.py", line 209, in execute_callable
    return self.python_callable(*self.op_args, **self.op_kwargs)
  File "/opt/airflow/dags/crypto_ml_pipeline.py", line 325, in retrain_model
    mlflow.log_artifact('/tmp/model.pkl', 'model')
  File "/home/airflow/.local/lib/python3.8/site-packages/mlflow/tracking/fluent.py", line 1130, in log_artifact
    MlflowClient().log_artifact(run_id, local_path, artifact_path)
  File "/home/airflow/.local/lib/python3.8/site-packages/mlflow/tracking/client.py", line 1928, in log_artifact
    self._tracking_client.log_artifact(run_id, local_path, artifact_path)
  File "/home/airflow/.local/lib/python3.8/site-packages/mlflow/tracking/_tracking_service/client.py", line 841, in log_artifact
    artifact_repo.log_artifact(local_path, artifact_path)
  File "/home/airflow/.local/lib/python3.8/site-packages/mlflow/store/artifact/s3_artifact_repo.py", line 176, in log_artifact
    self._upload_file(
  File "/home/airflow/.local/lib/python3.8/site-packages/mlflow/store/artifact/s3_artifact_repo.py", line 169, in _upload_file
    s3_client.upload_file(Filename=local_file, Bucket=bucket, Key=key, ExtraArgs=extra_args)
  File "/home/airflow/.local/lib/python3.8/site-packages/boto3/s3/inject.py", line 143, in upload_file
    return transfer.upload_file(
  File "/home/airflow/.local/lib/python3.8/site-packages/boto3/s3/transfer.py", line 292, in upload_file
    future.result()
  File "/home/airflow/.local/lib/python3.8/site-packages/s3transfer/futures.py", line 103, in result
    return self._coordinator.result()
  File "/home/airflow/.local/lib/python3.8/site-packages/s3transfer/futures.py", line 266, in result
    raise self._exception
  File "/home/airflow/.local/lib/python3.8/site-packages/s3transfer/tasks.py", line 139, in __call__
    return self._execute_main(kwargs)
  File "/home/airflow/.local/lib/python3.8/site-packages/s3transfer/tasks.py", line 162, in _execute_main
    return_value = self._main(**kwargs)
  File "/home/airflow/.local/lib/python3.8/site-packages/s3transfer/upload.py", line 758, in _main
    client.put_object(Bucket=bucket, Key=key, Body=body, **extra_args)
  File "/home/airflow/.local/lib/python3.8/site-packages/botocore/client.py", line 535, in _api_call
    return self._make_api_call(operation_name, kwargs)
  File "/home/airflow/.local/lib/python3.8/site-packages/botocore/client.py", line 963, in _make_api_call
    http, parsed_response = self._make_request(
  File "/home/airflow/.local/lib/python3.8/site-packages/botocore/client.py", line 986, in _make_request
    return self._endpoint.make_request(operation_model, request_dict)
  File "/home/airflow/.local/lib/python3.8/site-packages/botocore/endpoint.py", line 119, in make_request
    return self._send_request(request_dict, operation_model)
  File "/home/airflow/.local/lib/python3.8/site-packages/botocore/endpoint.py", line 198, in _send_request
    request = self.create_request(request_dict, operation_model)
  File "/home/airflow/.local/lib/python3.8/site-packages/botocore/endpoint.py", line 134, in create_request
    self._event_emitter.emit(
  File "/home/airflow/.local/lib/python3.8/site-packages/botocore/hooks.py", line 412, in emit
    return self._emitter.emit(aliased_event_name, **kwargs)
  File "/home/airflow/.local/lib/python3.8/site-packages/botocore/hooks.py", line 256, in emit
    return self._emit(event_name, kwargs)
  File "/home/airflow/.local/lib/python3.8/site-packages/botocore/hooks.py", line 239, in _emit
    response = handler(**kwargs)
  File "/home/airflow/.local/lib/python3.8/site-packages/botocore/signers.py", line 105, in handler
    return self.sign(operation_name, request)
  File "/home/airflow/.local/lib/python3.8/site-packages/botocore/signers.py", line 189, in sign
    auth.add_auth(request)
  File "/home/airflow/.local/lib/python3.8/site-packages/botocore/auth.py", line 418, in add_auth
    raise NoCredentialsError()
botocore.exceptions.NoCredentialsError: Unable to locate credentials
[2025-08-21T17:36:30.293+0000] {taskinstance.py:1398} INFO - Marking task as UP_FOR_RETRY. dag_id=crypto_ml_pipeline, task_id=retrain_model, execution_date=20250821T173610, start_date=20250821T173618, end_date=20250821T173630
[2025-08-21T17:36:30.297+0000] {standard_task_runner.py:104} ERROR - Failed to execute job 33 for task retrain_model (Unable to locate credentials; 2144)
[2025-08-21T17:36:30.339+0000] {local_task_job_runner.py:228} INFO - Task exited with return code 1
[2025-08-21T17:36:30.347+0000] {taskinstance.py:2776} INFO - 0 downstream tasks scheduled from follow-on schedule check
